<?xml version='1.0' encoding='utf-8'?>

<robot name="mmp_panda" version="1.0">

  <!-- GROUND LINK -->
  <link name ="ground_link">
    <inertial>
      <origin xyz="0.0 0.0 0.0" rpy="0 0 0" />
      <mass value="0.001" />
      <inertia ixx="1E-06" ixy="0.0" ixz="0.0" iyy="1E-06" iyz="0.0" izz="1E-06" />
    </inertial>
  </link>


  <!-- MOBILE BASE LINKS -->
  <link name ="base_x">
    <inertial>
      <origin xyz="0.0 0.0 0.0" rpy="0 0 0" />
      <mass value="0.001" />
      <inertia ixx="1E-06" ixy="0.0" ixz="0.0" iyy="1E-06" iyz="0.0" izz="1E-06" />
    </inertial>
  </link>

  <link name = "base_y">
    <inertial>
      <origin xyz="0.0 0.0 0.0" rpy="0 0 0" />
      <mass value = "0.001" />
      <inertia ixx="1E-06" ixy="0.0" ixz="0.0" iyy="1E-06" iyz="0.0" izz="1E-06" />
    </inertial>
  </link>

  <link name = "base_z">
    <inertial>
      <origin xyz="0.0 0.0 0.0" rpy="0 0 0" />
      <mass value = "0.001" />
      <inertia ixx="1E-06" ixy="0.0" ixz="0.0" iyy="1E-06" iyz="0.0" izz="1E-06" />
    </inertial>
  </link>

  <!-- MOBILE BASE + LINK 0 OF PANDA ARM -->
  <link name = "base_link">
    <inertial>
      <origin xyz="0.0 0.0 0.1757" rpy="0 0 0" />
      <mass value = "5.6" />
      <inertia ixx="0.5" ixy="0.0" ixz="0.0" iyy="0.5" iyz="0.0" izz="0.5" />
    </inertial>
    <!-- <visual>
      <geometry>
        <mesh filename="../../model/mmp_panda/meshes/panda_BaseCombo.obj" />
      </geometry>
    </visual> -->
    <collision>
      <geometry>
        <!--<mesh filename="../../../CS225a_TennisBot/Objects/Visual/CollisionMeshRacquetBasic.obj"/>-->
        <box size="0.5 0.5 0.5" />
      </geometry>
    </collision>
  </link>

  <!-- LEGS -->
  <!-- <link name = "leg_left_upper">
    <inertial>
      <origin xyz="0.0 0.0 0.0" rpy="0 0 0" />
      <mass value = "1.0" />
      <inertia ixx="1E-06" ixy="0.0" ixz="0.0" iyy="1E-06" iyz="0.0" izz="1E-06" />
    </inertial>
    <visual>
      <geometry>
          <cylinder radius="0.03" length="0.5" />
      </geometry>
    </visual>
    <collision>
      <geometry>
          <cylinder radius="0.03" length="0.5" />
      </geometry>
    </collision>
</link> -->
    <link name="LL_KOSY_L1">
        <inertial>
            <origin xyz="0.0140200000 0.0004000000 -0.0803900000" rpy="0 0 0" />
            <mass value="2.7752200000" />
            <inertia  ixx="0.0131418500" iyy="0.0127404000" izz="0.0055660580" ixy="0.0002490634" ixz="-0.0022168610" iyz="0.0003874600" />
        </inertial>
        <visual>
            <geometry>
                <mesh filename="../../model/toro/meshes/obj/left_lower_hip.stl.obj"/>
            </geometry>
        </visual>
<!--         <collision>
            <geometry>
                <capsule a="0.00832896 0.0145718 -0.112749" b="0.00832895 -0.0339701 -0.112749" radius="0.0755809"/>
                <mesh filename="../../model/toro/meshes/obj/left_lower_hip.stl.obj"/>
            </geometry>
        </collision> -->
      </link>

    <link name="LL_KOSY_L23">
        <inertial>
            <origin xyz="0.0004400000 0.0134800000 -0.1181100000" rpy="0 0 0" />
            <mass value="2.2450500000" />
            <inertia  ixx="0.0186767700" iyy="0.0182876800" izz="0.0041391160" ixy="0.0000149158" ixz="0.0000216283" iyz="-0.0029088950" />
        </inertial>
         <visual>
            <origin xyz="0 0 0" rpy= "-1.5708 0 0"/>
            <geometry>
                <mesh filename="../../model/toro/meshes/obj/kuka-link2.stl.obj"/>
            </geometry>
        </visual>
<!--         <collision>
            <origin xyz="0 0 0" rpy= "-1.5708 0 0"/>
            <geometry>
                <capsule a="0 0.037 0" b="0 0.0 -0.17" radius="0.0764886"/>
                <mesh filename="../../model/toro/meshes/obj/kuka-link2.stl.obj"/>
            </geometry>
        </collision> -->
      </link>

    <link name="LL_KOSY_L4">
        <inertial>
            <origin xyz="0.0001800000 -0.0197800000 0.0475700000" rpy="0 0 0" />
            <mass value="2.6274500000" />
            <inertia  ixx="0.0181853400" iyy="0.0177957500" izz="0.0046458290" ixy="0.0000220452" ixz="0.0000193978" iyz="-0.0018474590" />
        </inertial>       
         <visual>
            <origin  xyz="0 0 -0.399900088" rpy="0 3.1416 0"/>
            <geometry>
                <mesh filename="../../model/toro/meshes/obj/kuka-link3.stl.obj"/>
            </geometry>
        </visual>
<!--         <collision>
            <origin  xyz="0 0 -0.399900088" rpy="0 3.1416 0"/>
            <geometry>
                <mesh filename="../../model/toro/meshes/obj/kuka-link3.stl.obj"/>
            </geometry>
        </collision> -->
      </link>


    <link name="LL_KOSY_L56">
        <inertial>
            <origin xyz="-0.0017200000 0.0075200000 -0.1697300000" rpy="0 0 0" />
            <mass value="5.7035400000" />
            <inertia  ixx="0.0904466300" iyy="0.0891587900" izz="0.0139048900" ixy="-0.0001614719" ixz="0.0007332664" iyz="-0.0098185250" />
        </inertial>
         <visual>
            <geometry>
                <mesh filename="../../model/toro/meshes/obj/left_calf.stl.obj"/>
            </geometry>
        </visual>
<!--         <collision>
            <geometry>
                <mesh filename="../../model/toro/meshes/obj/left_calf.stl.obj"/>
            </geometry>
        </collision> -->
    </link>

    <link name="RL_KOSY_L1">
        <inertial>
            <origin xyz="0.0140200000 -0.0003900000 -0.0807700000" rpy="0 0 0" />
            <mass value="2.7752200000" />
            <inertia  ixx="0.0132241200" iyy="0.0128226400" izz="0.0055660800" ixy="-0.0002500743" ixz="-0.0022333460" iyz="-0.0004034797" />
        </inertial>
        <visual>
            <origin xyz="0 0 0" rpy="0 0 0" />
            <geometry>
                <mesh filename="../../model/toro/meshes/obj/right_lower_hip.stl.obj"/>
            </geometry>
        </visual>
<!--         <collision>
            <origin xyz="0 0 0" rpy="0 0 0" />
            <geometry>
                <capsule a="0.00832896 0.0340227 -0.112749" b="0.00832895 -0.0145192 -0.112749" radius="0.0755809"/>
                <mesh filename="../../model/toro/meshes/obj/right_lower_hip.stl.obj"/>
            </geometry>
        </collision>     -->    
    </link>

    <link name="RL_KOSY_L23">
        <inertial>
            <origin xyz="-0.0004400000 -0.0134800000 -0.1181100000" rpy="0 0 0" />
            <mass value="2.2450500000" />
            <inertia  ixx="0.0186767700" iyy="0.0182876800" izz="0.0041391160" ixy="0.0000149158" ixz="-0.0000216283" iyz="0.0029088950" />
        </inertial>
        <visual>
        <origin  xyz="0 0 0" rpy="-1.5708 0 3.1416 "/>
            <geometry>
                <mesh filename="../../model/toro/meshes/obj/kuka-link2.stl.obj"/>
            </geometry>
        </visual>
<!--         <collision>
        <origin  xyz="0 0 0" rpy="-1.5708 0 3.1416 "/>
            <geometry>
                <capsule a="0 -0.037 0" b="0 0.0 -0.17" radius="0.0764886"/>
                <mesh filename="../../model/toro/meshes/obj/kuka-link2.stl.obj"/>
            </geometry>
        </collision> -->
    </link>

    <link name="RL_KOSY_L4">
        <inertial>
            <origin xyz="-0.0001800000 0.0197800000 0.0475700000" rpy="0 0 0" />
            <mass value="2.6274500000" />
            <inertia  ixx="0.0181853400" iyy="0.0177957500" izz="0.0046458290" ixy="0.0000220452" ixz="-0.0000193978" iyz="0.0018474590" />
        </inertial>
        <visual>
            <origin  xyz="0 0 -0.399900088" rpy="3.1416 0 0"/>
            <geometry>
                <mesh filename="../../model/toro/meshes/obj/kuka-link3.stl.obj"/>
            </geometry>
        </visual>
<!--         <collision>
            <origin  xyz="0 0 -0.399900088" rpy="3.1416 0 0"/>
            <geometry>
                <mesh filename="../../model/toro/meshes/obj/kuka-link3.stl.obj"/>
            </geometry>
        </collision> -->
    </link>

    <link name="RL_KOSY_L56">
        <inertial>
            <origin xyz="-0.0013700000 -0.0074900000 -0.1697900000" rpy="0 0 0" />
            <mass value="5.7035400000" />
            <inertia  ixx="0.0904821100" iyy="0.0891927700" izz="0.0139187300" ixy="0.0002627257" ixz="0.0006447136" iyz="0.0098359460" />
        </inertial>
        <visual>
            <geometry>
                <mesh filename="../../model/toro/meshes/obj/right_calf.stl.obj"/>
            </geometry>
        </visual>
<!--         <collision>
            <geometry>
                <mesh filename="../../model/toro/meshes/obj/right_calf.stl.obj"/>
            </geometry>
        </collision> -->
    </link>

    <link name="LL_foot">
        <inertial>
            <origin xyz="0 0 0" rpy="0 0 0" />
            <mass value="1.5" />
            <inertia  ixx="0.0904821100" iyy="0.0891927700" izz="0.0139187300" ixy="0.0002627257" ixz="0.0006447136" iyz="0.0098359460" />
        </inertial>
        <visual>
          <geometry>
            <!--<mesh filename="../../../CS225a_TennisBot/Objects/Visual/CollisionMeshRacquetBasic.obj"/>-->
            <box size="0.2 0.2 0.05" />
          </geometry>
        </visual>
    <collision>
      <geometry>
        <!--<mesh filename="../../../CS225a_TennisBot/Objects/Visual/CollisionMeshRacquetBasic.obj"/>-->
        <box size="0.2 0.2 0.05" />
      </geometry>
    </collision>
    </link>

    <link name="RL_foot">
        <inertial>
            <origin xyz="0 0 0" rpy="0 0 0" />
            <mass value="1.5" />
            <inertia  ixx="0.0904821100" iyy="0.0891927700" izz="0.0139187300" ixy="0.0002627257" ixz="0.0006447136" iyz="0.0098359460" />
        </inertial>
        <visual>
          <geometry>
            <!--<mesh filename="../../../CS225a_TennisBot/Objects/Visual/CollisionMeshRacquetBasic.obj"/>-->
            <box size="0.2 0.2 0.05" />
          </geometry>
        </visual>
    <collision>
      <geometry>
        <!--<mesh filename="../../../CS225a_TennisBot/Objects/Visual/CollisionMeshRacquetBasic.obj"/>-->
        <box size="0.2 0.2 0.05" />
      </geometry>
    </collision>
    </link>

  <!-- PANDA ARM LINKS -->
<!--<link name="link0">
    <inertial>
      <origin xyz="0 0 0.05" rpy="0 0 0" />
      <mass value="4" />
      <inertia ixx="0.4" iyy="0.4" izz="0.4" ixy="0" ixz="0" iyz="0" />
    </inertial>
    <visual>
      <geometry>
        <mesh filename="../../../model/panda/meshes/visual/link0.obj"/>
      </geometry>
    </visual>
<!      <collision>
        <geometry>
          <mesh filename="../../../model/panda/meshes/collision/link0.obj"/>
        </geometry>
      </collision>
  </link> -->
  <link name="link1">
    <inertial>
      <origin xyz="0 0 -0.07" rpy="0 -0 0" />
      <mass value="4" />
      <inertia ixx="0.3" iyy="0.3" izz="0.3" ixy="0" ixz="0" iyz="0" />
    </inertial>
    <visual>
      <geometry>
        <mesh filename="../../model/panda/meshes/visual/link1.obj"/>
      </geometry>
    </visual>
    <!-- <collision>
      <geometry>
        <mesh filename="../../../model/panda/meshes/collision/link1.obj"/>
      </geometry>
    </collision> -->
  </link>
  <link name="link2">
    <inertial>
      <origin xyz="0 -0.1 0" rpy="0 -0 0" />
      <mass value="3" />
      <inertia ixx="0.3" iyy="0.3" izz="0.3" ixy="0" ixz="0" iyz="0" />
    </inertial>
    <visual>
      <geometry>
        <mesh filename="../../model/panda/meshes/visual/link2.obj"/>
      </geometry>
    </visual>
    <!-- <collision>
      <geometry>
        <mesh filename="../../../model/panda/meshes/collision/link2.obj"/>
      </geometry>
    </collision> -->
  </link>
  <link name="link3">
    <inertial>
      <origin xyz="0.04 0 -0.05" rpy="0 -0 0" />
      <mass value="3" />
      <inertia ixx="0.2" iyy="0.2" izz="0.2" ixy="0" ixz="0" iyz="0" />
    </inertial>
    <visual>
      <geometry>
        <mesh filename="../../model/panda/meshes/visual/link3.obj"/>
      </geometry>
    </visual>
    <!-- <collision>
      <geometry>
        <mesh filename="../../../model/panda/meshes/collision/link3.obj"/>
      </geometry>
    </collision> -->
  </link>
  <link name="link4">
    <inertial>
      <origin xyz="-0.04 0.05 0" rpy="0 -0 0" />
      <mass value="3" />
      <inertia ixx="0.2" iyy="0.2" izz="0.2" ixy="0" ixz="0" iyz="0" />
    </inertial>
    <visual>
      <geometry>
        <mesh filename="../../model/panda/meshes/visual/link4.obj"/>
      </geometry>
    </visual>
<!--       <collision>
      <geometry>
        <mesh filename="../../../model/panda/meshes/collision/link4.obj"/>
      </geometry>
    </collision> -->
  </link>
  <link name="link5">
    <inertial>
      <origin xyz="0 0 -0.15" rpy="0 -0 0" />
      <mass value="3" />
      <inertia ixx="0.2" iyy="0.2" izz="0.2" ixy="0" ixz="0" iyz="0" />
    </inertial>
    <visual>
      <geometry>
        <mesh filename="../../model/panda/meshes/visual/link5.obj"/>
      </geometry>
    </visual>
<!--       <collision>
      <geometry>
        <mesh filename="../../../model/panda/meshes/collision/link5.obj"/>
      </geometry>
    </collision> -->
  </link>
  <link name="link6">
    <inertial>
      <origin xyz="0.06 0 0" rpy="0 -0 0" />
      <mass value="2" />
      <inertia ixx="0.1" iyy="0.1" izz="0.1" ixy="0" ixz="0" iyz="0" />
    </inertial>
    <visual>
      <geometry>
        <mesh filename="../../model/panda/meshes/visual/link6.obj"/>
      </geometry>
    </visual>
    <!-- <collision>
      <geometry>
        <mesh filename="../../../model/panda/meshes/collision/link6.obj"/>
      </geometry>
    </collision> -->
  </link>
  <link name="link7">
    <inertial>
      <origin xyz="0 0 0" rpy="0 -0 0" />
      <mass value="0.03268873" /> <!-- racquet weight 11.3 oz from google -> .3203496kg/9.8m/s^2 = .03268873 !-->
      <inertia ixx="0.09" iyy="0.05" izz="0.07" ixy="0" ixz="0" iyz="0" />
    </inertial>
    <visual>
      <geometry>
        <mesh filename="../../model/panda/meshes/visual/link7.obj"/>
      </geometry>
    </visual>
    <!-- <collision>
      <geometry>
        <mesh filename="../../../model/panda/meshes/collision/link7.obj"/>
      </geometry>
    </collision> -->
  </link>

  <link name="racquetlink">
    <inertial>
      <origin xyz="0 -0 0.0" rpy="0 -0 0" /><!--0.5842-->
      <mass value=".3203496" />
      <inertia ixx="0.3" iyy="0.3" izz="0.3" ixy="0" ixz="0" iyz="0" />
    </inertial>
    <visual>
      <origin xyz="0 -0 0.05" rpy="0 -0 0" /><!--0.5842-->
      <geometry>
        <!--<mesh filename="../../../CS225a_TennisBot/Objects/Visual/CollisionMeshRacquetBasic.obj"/>-->
        <box size="0.25 0.25 0.05" />
      </geometry>
    </visual>
    <collision>
      <origin xyz="0 -0 0.05" rpy="0 -0 0" /><!--0.5842-->
      <geometry>
        <!--<mesh filename="../../../CS225a_TennisBot/Objects/Visual/CollisionMeshRacquetBasic.obj"/>-->
	<box size="0.25 0.25 0.05" />
      </geometry>
    </collision>
    </link>


  <!-- JOINTS -->
  <joint name = "base_prismatic_x" type = "prismatic">
    <origin xyz = "0 0 0" rpy = "0 0 0"/>
    <parent link = "ground_link" />
    <child link= "base_x"/>
    <axis xyz = "1 0 0" />
    <limit effort="0" velocity="10.0" />
  </joint>

  <joint name = "base_prismatic_y" type = "prismatic">
    <origin xyz = "0 0 0" rpy = "0 0 0"/>
    <parent link = "base_x" />
    <child link= "base_y"/>
    <axis xyz = "0 1 0" />
    <limit effort="0" velocity="10.0" />
  </joint>

  <joint name = "base_prismatic_z" type = "prismatic">
    <origin xyz = "0 0 0" rpy = "0 0 0"/>
    <parent link = "base_y" />
    <child link= "base_z"/>
    <axis xyz = "0 0 1" />
        <!-- <limit effort="20.0" velocity="20.0" /> -->
      <limit effort="100" lower="-100" upper="100" velocity="21.3"/>
  </joint>

  <joint name = "base_revolute" type = "revolute">
    <origin xyz = "0 0 0.0" rpy = "0 0 0"/>
    <parent link = "base_z" />
    <child link= "base_link"/>
    <axis xyz = "0 0 1" />
    <limit effort="87" lower="-2.8973" upper="2.8973" velocity="2.1750" />
  </joint>
<!--
  <joint name = "base_prismatic_link0" type = "prismatic">
    <origin xyz = "0 0 0.33" rpy = "0 0 0"/>
    <parent link = "base_link" />
    <child link= "link0"/>
    <axis xyz = "0 0 1" />
    <limit effort="87" lower="-2.8973" upper="2.8973" velocity="2.1750" />
  </joint>
-->
  <joint name="joint1" type="revolute">
      <safety_controller k_position="100.0" k_velocity="100.0" soft_lower_limit="-2.8973" soft_upper_limit="2.8973"/>
      <origin rpy="0 0 1.5708" xyz="0 0 0.333"/>
      <parent link="base_link"/>
      <child link="link1"/>
      <axis xyz="0 0 1"/>
      <calibration falling="-80.0" />
      <limit effort="100" lower="-2.8973" upper="2.8973" velocity="100.0"/>
  </joint>

  <joint name="joint2" type="revolute">
      <safety_controller k_position="100.0" k_velocity="40.0" soft_lower_limit="-1.7628" soft_upper_limit="1.7628"/>
      <origin rpy="-1.57079632679 0 0" xyz="0 0 0"/>
      <parent link="link1"/>
      <child link="link2"/>
      <axis xyz="0 0 1"/>
      <calibration falling="-45.0" />
      <limit effort="87" lower="-1.7628" upper="1.7628" velocity="2.1750"/>
  </joint>

  <joint name="joint3" type="revolute">
      <safety_controller k_position="100.0" k_velocity="40.0" soft_lower_limit="-2.8973" soft_upper_limit="2.8973"/>
      <origin rpy="1.57079632679 0 0" xyz="0 -0.316 0"/>
      <parent link="link2"/>
      <child link="link3"/>
      <axis xyz="0 0 1"/>
      <limit effort="87" lower="-2.8973" upper="2.8973" velocity="2.1750"/>
  </joint>

  <joint name="joint4" type="revolute">
      <safety_controller k_position="100.0" k_velocity="40.0" soft_lower_limit="-3.0718" soft_upper_limit="-0.0698"/>
      <origin rpy="1.57079632679 0 0" xyz="0.0825 0 0"/>
      <parent link="link3"/>
      <child link="link4"/>
      <axis xyz="0 0 1"/>
      <calibration falling="-125.0" />
      <limit effort="87" lower="-3.0718" upper="-0.0698" velocity="2.1750"/>
  </joint>

  <joint name="joint5" type="revolute">
      <safety_controller k_position="100.0" k_velocity="40.0" soft_lower_limit="-2.8973" soft_upper_limit="2.8973"/>
      <origin rpy="-1.57079632679 0 0" xyz="-0.0825 0.384 0"/>
      <parent link="link4"/>
      <child link="link5"/>
      <axis xyz="0 0 1"/>
      <limit effort="12" lower="-2.8973" upper="2.8973" velocity="2.6100"/>
  </joint>

  <joint name="joint6" type="revolute">
      <safety_controller k_position="100.0" k_velocity="40.0" soft_lower_limit="-0.0175" soft_upper_limit="3.7525"/>
      <origin rpy="1.57079632679 0 0" xyz="0 0 0"/>
      <parent link="link5"/>
      <child link="link6"/>
      <axis xyz="0 0 1"/>
      <calibration falling="80.0" />
      <limit effort="12" lower="-0.0175" upper="3.7525" velocity="2.6100"/>
  </joint>

  <joint name="joint7" type="revolute">
      <safety_controller k_position="100.0" k_velocity="40.0" soft_lower_limit="-2.8973" soft_upper_limit="2.8973"/>
      <origin rpy="1.57079632679 0 0" xyz="0.088 0 0"/>
      <parent link="link6"/>
      <child link="link7"/>
      <axis xyz="0 0 1"/>
      <limit effort="12" lower="-2.8973" upper="2.8973" velocity="2.6100"/>
  </joint>

<joint name="joint8" type="fixed">
      <safety_controller k_position="100.0" k_velocity="40.0" soft_lower_limit="-2.8973" soft_upper_limit="2.8973"/>
      <origin rpy="1.57079632679 0 0" xyz="0.0 0 0"/>
      <parent link="link7"/>
      <child link="racquetlink"/>
      <axis xyz="0 0 1"/>
      <limit effort="12" lower="-2.8973" upper="2.8973" velocity="2.6100"/>
  </joint>

<!--
   <joint name="joint1" type="revolute">
    <origin xyz="0 0 0.48643" rpy="3.1416 2.7629E-18 -3.14" />
    <parent link="base_link" />
    <child link="link1" />
    <axis xyz="0 0 1" />
    <limit lower="-10" upper="10" effort="39" velocity="0.8727" />
  </joint>

  <joint name="joint2" type="revolute">
    <origin xyz="0 0.005375 -0.12838" rpy="1.5708 2.1343E-17 -1.1102E-16" />
    <parent link="link1" />
    <child link="link2" />
    <axis xyz="0 0 1" />
    <calibration falling="-45.0" />
    <limit lower="-10" upper="10" effort="39" velocity="0.8727" />
  </joint>

  <joint name="joint3" type="revolute">
    <origin xyz="0 -0.21038 -0.006375" rpy="-1.5708 1.2326E-32 -2.9122E-16" />
    <parent link="link2" />
    <child link="link3" />
    <axis xyz="0 0 1" />
    <limit lower="-10" upper="10" effort="39" velocity="0.8727" />
  </joint>

  <joint name="joint4" type="revolute">
    <origin xyz="0 0.006375 -0.21038" rpy="1.5708 -6.6954E-17 -1.6653E-16" />
    <parent link="link3" />
    <child link="link4" />
    <axis xyz="0 0 1" />
    <calibration falling="-125.0" />
    <limit lower="-10" upper="10" effort="39" velocity="0.8727" />
  </joint>

  <joint name="joint5" type="revolute">
    <origin xyz="0 -0.20843 -0.006375" rpy="-1.5708 2.2204E-16 -6.373E-17" />
    <parent link="link4" />
    <child link="link5" />
    <axis xyz="0 0 1" />
    <limit lower="-10" upper="10" effort="9" velocity="0.8727" />
  </joint>

  <joint name="joint6" type="revolute">
    <origin xyz="0 0.00017505 -0.10593" rpy="1.5708 9.2076E-28 -8.2157E-15" />
    <parent link="link5" />
    <child link="link6" />
    <axis xyz="0 0 1" />
    <calibration falling="80.0" />
    <limit lower="-10" upper="10" effort="9" velocity="0.8727" />
  </joint>

  <joint name="joint7" type="revolute">
    <origin xyz="0 -0.10593 -0.00017505" rpy="-1.5708 -5.5511E-17 9.6396E-17" />
    <parent link="link6" />
    <child link="link7" />
    <axis xyz="0 0 1" />
    <limit lower="-10" upper="10" effort="9" velocity="0.8727" />
  </joint>
-->

<!-- <joint name="joint_leg_left_upper" type="revolute">
      <origin rpy="0 3.14159 0" xyz="0 0.333 0"/>
      <parent link="base_link"/>
      <child link="leg_left_upper"/>
      <axis xyz="0 1 0"/>
      <limit effort="100" lower="-2.8973" upper="2.8973" velocity="100.0"/>
</joint> -->

    <joint name="joint_leg_left1" type="fixed">
        <origin xyz="0.0000000000 0.1000000000 0.1" rpy="0 0 0" />
        <parent link="base_link"/>
        <child link="LL_KOSY_L1"/> 
        <limit lower="-0.7804" upper="1.5708" effort="176" velocity="1.9199" />
        <axis xyz= " 1 0 0 "/>
    </joint>

    <joint name="joint_leg_left2" type="revolute">
        <origin xyz="0.0000000000 0.0350000000 -0.1200000000" rpy="0 0 0" />
        <parent link="LL_KOSY_L1"/>
        <child link="LL_KOSY_L23"/> 
        <limit lower="-2.0071" upper="1.5708" effort="100" velocity="2.7402" />
        <axis xyz="0 1 0"/>
    </joint>

    <joint name="joint_leg_left3" type="fixed">
        <parent link="LL_KOSY_L23"/>
        <child link="LL_KOSY_L4"/> 
        <limit lower="-2.0944" upper="2.0944" effort="100" velocity="2.7402" />
        <axis xyz="0 0 1"/>
    </joint>

    <joint name="joint_leg_left4" type="revolute">
        <origin xyz="0.0000000000 0.0000000000 -0.3999000880" rpy="0 0 0" />
        <parent link="LL_KOSY_L4"/>
        <child link="LL_KOSY_L56"/> 
        <limit lower="-1.8326" upper="1.8326" effort="165" velocity="3.0718" />
        <axis xyz="0 1 0"/>
    </joint>

    <joint name="joint_leg_left5" type="revolute">
        <origin xyz="0.0000000000 0.0000000000 -0.3999000880" rpy="0 0 0" />
        <parent link="LL_KOSY_L56"/> 
        <child link="LL_foot"/>
        <limit lower="-1.8326" upper="1.8326" effort="165" velocity="3.0718" />
         <axis xyz="0 1 0"/>
    </joint>

    <joint name="joint_leg_right1" type="fixed">
        <origin xyz="-0.0000000000 -0.1000000000 0.1" rpy="0 0 0" />
        <parent link="base_link"/>
        <child link="RL_KOSY_L1"/> 
        <limit effort="176" velocity="1.9199" lower="-1.5708" upper="0.7854" />
        <axis xyz="1 0 0"/>   
    </joint>

    <joint name="joint_leg_right2" type="revolute">
        <origin xyz="-0.0000000000 -0.0350000000 -0.1200000000" rpy="0 0 0" />
        <parent link="RL_KOSY_L1"/>
        <child link="RL_KOSY_L23"/> 
        <limit lower="-2.0071" upper="1.5708" effort="100" velocity="2.7402" />
        <axis xyz="0 1 0"/>    
    </joint>

    <joint name="joint_leg_right3" type="fixed">
        <parent link="RL_KOSY_L23"/>
        <child link="RL_KOSY_L4"/> 
        <limit lower="-2.0944" upper="2.0944" effort="100" velocity="2.7402" />
        <axis xyz="0 0 1"/>     
    </joint>

    <joint name="joint_leg_right4" type="revolute">
        <origin xyz="0.0000000000 0.0000000000 -0.3999000880" rpy="0 0 0" />
        <parent link="RL_KOSY_L4"/>
        <child link="RL_KOSY_L56"/> 
        <limit lower="-1.8326" upper="1.8326" effort="165" velocity="3.0718" />
         <axis xyz="0 1 0"/>
    </joint>

    <joint name="joint_leg_right5" type="revolute">
        <origin xyz="0.0000000000 0.0000000000 -0.3999000880" rpy="0 0 0" />
        <parent link="RL_KOSY_L56"/> 
        <child link="RL_foot"/>
        <limit lower="-1.8326" upper="1.8326" effort="165" velocity="3.0718" />
         <axis xyz="0 1 0"/>
    </joint>
</robot>
